Workbook

Sheet Dashboard
A1: JOB SEARCH DASHBOARD
A2: Every figure below updates automatically from the Applications tab (rows 3–502).
A4: PIPELINE FUNNEL | E4: WHAT'S ACTUALLY WORKING
A5: Stage | B5: Count | C5: % of Applied | E5: Source | F5: Applied | G5: Interviews
A6: Applications submitted | B6: =COUNT(Applications!$H$3:$H$502) | E6: LinkedIn | F6: =COUNTIFS(Applications!$F$3:$F$502,$E6,Applications!$H$3:$H$502,">0") | G6: =SUMPRODUCT((Applications!$F$3:$F$502=$E6)*((Applications!$I$3:$I$502="Interview")+(Applications!$I$3:$I$502="Final Round")+(Applications!$I$3:$I$502="Offer")))
A7: Reached phone screen | B7: =COUNTIF(Applications!$I$3:$I$502,"Phone Screen")+COUNTIF(Applications!$I$3:$I$502,"Interview")+COUNTIF(Applications!$I$3:$I$502,"Final Round")+COUNTIF(Applications!$I$3:$I$502,"Offer") | C7: =IFERROR(B7/$B$6,"") | E7: Company Site | F7: =COUNTIFS(Applications!$F$3:$F$502,$E7,Applications!$H$3:$H$502,">0") | G7: =SUMPRODUCT((Applications!$F$3:$F$502=$E7)*((Applications!$I$3:$I$502="Interview")+(Applications!$I$3:$I$502="Final Round")+(Applications!$I$3:$I$502="Offer")))
A8: Reached interview | B8: =COUNTIF(Applications!$I$3:$I$502,"Interview")+COUNTIF(Applications!$I$3:$I$502,"Final Round")+COUNTIF(Applications!$I$3:$I$502,"Offer") | C8: =IFERROR(B8/$B$6,"") | E8: Referral | F8: =COUNTIFS(Applications!$F$3:$F$502,$E8,Applications!$H$3:$H$502,">0") | G8: =SUMPRODUCT((Applications!$F$3:$F$502=$E8)*((Applications!$I$3:$I$502="Interview")+(Applications!$I$3:$I$502="Final Round")+(Applications!$I$3:$I$502="Offer")))
A9: Reached final round | B9: =COUNTIF(Applications!$I$3:$I$502,"Final Round")+COUNTIF(Applications!$I$3:$I$502,"Offer") | C9: =IFERROR(B9/$B$6,"") | E9: Recruiter | F9: =COUNTIFS(Applications!$F$3:$F$502,$E9,Applications!$H$3:$H$502,">0") | G9: =SUMPRODUCT((Applications!$F$3:$F$502=$E9)*((Applications!$I$3:$I$502="Interview")+(Applications!$I$3:$I$502="Final Round")+(Applications!$I$3:$I$502="Offer")))
A10: Offers received | B10: =COUNTIF(Applications!$I$3:$I$502,"Offer") | C10: =IFERROR(B10/$B$6,"") | E10: Indeed | F10: =COUNTIFS(Applications!$F$3:$F$502,$E10,Applications!$H$3:$H$502,">0") | G10: =SUMPRODUCT((Applications!$F$3:$F$502=$E10)*((Applications!$I$3:$I$502="Interview")+(Applications!$I$3:$I$502="Final Round")+(Applications!$I$3:$I$502="Offer")))
E11: Glassdoor | F11: =COUNTIFS(Applications!$F$3:$F$502,$E11,Applications!$H$3:$H$502,">0") | G11: =SUMPRODUCT((Applications!$F$3:$F$502=$E11)*((Applications!$I$3:$I$502="Interview")+(Applications!$I$3:$I$502="Final Round")+(Applications!$I$3:$I$502="Offer")))
A12: WHERE THINGS STAND | E12: Job Board | F12: =COUNTIFS(Applications!$F$3:$F$502,$E12,Applications!$H$3:$H$502,">0") | G12: =SUMPRODUCT((Applications!$F$3:$F$502=$E12)*((Applications!$I$3:$I$502="Interview")+(Applications!$I$3:$I$502="Final Round")+(Applications!$I$3:$I$502="Offer")))
A13: Still active (no outcome yet) | B13: =SUMPRODUCT((Applications!$H$3:$H$502<>"")*(Applications!$J$3:$J$502="")) | E13: Networking | F13: =COUNTIFS(Applications!$F$3:$F$502,$E13,Applications!$H$3:$H$502,">0") | G13: =SUMPRODUCT((Applications!$F$3:$F$502=$E13)*((Applications!$I$3:$I$502="Interview")+(Applications!$I$3:$I$502="Final Round")+(Applications!$I$3:$I$502="Offer")))
A14: Not applied yet | B14: =COUNTIF(Applications!$I$3:$I$502,"To Apply") | E14: Other | F14: =COUNTIFS(Applications!$F$3:$F$502,$E14,Applications!$H$3:$H$502,">0") | G14: =SUMPRODUCT((Applications!$F$3:$F$502=$E14)*((Applications!$I$3:$I$502="Interview")+(Applications!$I$3:$I$502="Final Round")+(Applications!$I$3:$I$502="Offer")))
A15: Rejected | B15: =COUNTIF(Applications!$J$3:$J$502,"Rejected")
A16: Ghosted | B16: =COUNTIF(Applications!$J$3:$J$502,"Ghosted")
A17: Withdrawn | B17: =COUNTIF(Applications!$J$3:$J$502,"Withdrawn") | E17: HOW TO USE THIS TRACKER
A18: Offers accepted | B18: =COUNTIF(Applications!$J$3:$J$502,"Offer Accepted") | E18: 1. Add one row per role on the Applications tab. Row 3 is an example — overwrite it.
A19: Total roles tracked | B19: =COUNTA(Applications!$A$3:$A$502) | E19: 2. Stage = the furthest point you have reached. Move it forward as you progress.
E20: 3. Outcome = only fill this in when a role ends. Blank means it is still live.
A21: ACTION NEEDED | E21: 4. Days Since Applied fills itself in. It turns orange after 14 days with no outcome.
A22: Applied in the last 7 days | B22: =COUNTIFS(Applications!$H$3:$H$502,">="&TODAY()-7) | E22: 5. A Follow-Up Date turns red on the day it is due, so filter that column to plan your week.
A23: Applied in the last 30 days | B23: =COUNTIFS(Applications!$H$3:$H$502,">="&TODAY()-30) | E23: 6. Dropdown options live on the Lists tab — add your own values there any time.
A24: Follow-ups due or overdue | B24: =SUMPRODUCT((Applications!$N$3:$N$502<>"")*(Applications!$N$3:$N$502<=TODAY())*(Applications!$J$3:$J$502="")) | E24: 7. Use the filter arrows on row 2 to slice by stage, source, or priority.
A25: Waiting 14+ days with no reply | B25: =SUMPRODUCT((Applications!$H$3:$H$502<>"")*(Applications!$H$3:$H$502<TODAY()-14)*(Applications!$J$3:$J$502="")*(Applications!$I$3:$I$502="Applied"))
A26: High-priority roles still open | B26: =SUMPRODUCT((Applications!$R$3:$R$502="High")*(Applications!$J$3:$J$502=""))
A30: Note: dashboard formulas cover Applications rows 3–502. Extend the ranges if you add more than 500 roles.

Sheet Applications
A1: JOB APPLICATION TRACKER | E1: Fill in every column except Days Since Applied (grey, auto-calculated). Row 3 is an example — overwrite or delete it.
A2: Company | B2: Role / Title | C2: Location | D2: Work Setup | E2: Salary / Comp | F2: Source | G2: Job Link | H2: Date Applied | I2: Stage | J2: Outcome | K2: Days Since Applied | L2: Last Contact | M2: Next Action | N2: Follow-Up Date | O2: Contact Name | P2: Contact Email | Q2: Resume Version | R2: Priority | S2: Notes
A3: Detajl | B3: Civil Engineer – Designer (traffic/municipal infrastructure) | C3: Vipava, SI | F3: Job Board | H3: 46231 | I3: Applied | K3: =IF($H3="","",TODAY()-$H3) | O3: Marko Lavrenčič | P3: marko@detajl.eu | Q3: slovenia/2026_07_28_detajl_marko_lavrencic | R3: Medium | S3: Reg. RC23034. No driving license (candidate lacks one) — omitted, not raised.
A4: Energetika Ljubljana (JHL) | B4: Planning Development Solutions (energy systems – heat/gas supply) | C4: Ljubljana, SI | F4: Job Board | H4: 46231 | I4: Applied | K4: =IF($H4="","",TODAY()-$H4) | O4: Janka Likosar | P4: kadri-jpe@jhl.si | Q4: slovenia/2026_07_28_energetika_ljubljana_janka_likosar | R4: Medium | S4: Reg. RD22005. Domain stretch (energy vs. BIM/civil) — leans on MEP coordination + energy-mgmt coursework.
A5: Hidrotehnik | B5: Design Engineer – Water Management | C5: Ljubljana, SI | D5: Hybrid | F5: Job Board | H5: 46231 | I5: Applied | K5: =IF($H5="","",TODAY()-$H5) | O5: Matthew B. | P5: info@hidrotehnik.si | Q5: slovenia/2026_07_28_hidrotehnik_matthew_b | R5: Medium | S5: Reg. RD21686. Honest about <2yr experience gap and A1 Slovene vs. required fluent.
A6: Atrij | B6: Speculative – BIM/digitalization pitch (advertised role: building-structures drafter) | C6: Odranci, SI | F6: Job Board | H6: 46231 | I6: Applied | K6: =IF($H6="","",TODAY()-$H6) | O6: Nina Kolarič Tibaut | P6: atrij@atrij.si | Q6: slovenia/2026_07_28_atrij_nina_kolaric_tibaut | R6: Low | S6: Reg. RC87935 (advertised role skipped, not a match). Speculative pitch — 10-person firm, no existing BIM function.
A7: RMB Modul | B7: Cost Estimation / 5D Quantity Take-off | C7: Velika Polana, SI | F7: Job Board | H7: 46231 | I7: Applied | K7: =IF($H7="","",TODAY()-$H7) | O7: Stojan Špitalar | P7: stojan@rmbmodul.com | Q7: slovenia/2026_07_28_rmb_modul_stojan_spitalar | R7: Medium | S7: Reg. PZ46034. Strong content match (5D QTO). Honest that candidate has zero German (posting states mandatory).
A8: HNG d.o.o. | B8: Student Work – Inventory of Water Facilities, Devices & Arrangements | C8: Mengeš, SI | D8: Hybrid | F8: Job Board | G8: https://popr.uni-lj.si/student/employers.html?employer=441557&page=employer | H8: 46231 | I8: Applied | K8: =IF($H8="","",TODAY()-$H8) | Q8: slovenia/2026_07_28_hng_doo | R8: Medium | S8: Student-work listing via UL popr portal (no email; apply through portal). Surfaced real ArcGIS/hydrology coursework.
A9: Zagožen d.o.o. | B9: Utility/Civil/Mechanical Engineer – utility infrastructure | C9: Žalec, SI | F9: Job Board | G9: https://popr.uni-lj.si/student/employers.html?employer=441554&page=employer | H9: 46231 | I9: Applied | K9: =IF($H9="","",TODAY()-$H9) | O9: Kadrovska služba (HR) | Q9: slovenia/2026_07_28_zagozen_doo | R9: High | S9: Full-time, explicitly targets 0-2 yrs experience. Water/sewage infrastructure — strong natural fit. UL popr portal.
A10: Saning d.o.o. | B10: Speculative – BIM/digitalization pitch (advertised role: site operations manager) | C10: Kranj, SI | F10: Job Board | G10: https://popr.uni-lj.si/student/employers.html?employer=441546&page=employer | H10: 46231 | I10: Applied | K10: =IF($H10="","",TODAY()-$H10) | Q10: slovenia/2026_07_28_saning_doo | R10: Low | S10: Advertised role skipped as mismatch. Speculative pitch — no existing BIM function despite larger multi-country group.
A11: DOTES d.o.o. | B11: Speculative – BIM/digitalization pitch (advertised: scholarship for enrolled students) | C11: Dolenja vas, SI | F11: Job Board | G11: https://popr.uni-lj.si/student/employers.html?employer=441544&page=employer | H11: 46231 | I11: Applied | K11: =IF($H11="","",TODAY()-$H11) | P11: info@dotes.si | Q11: slovenia/2026_07_28_dotes_doo | R11: Low | S11: Scholarship required proof of enrollment — ineligible post-graduation. Redirected to speculative BIM pitch, hooked on their new 3D-visualization service.
A12: IKB d.o.o. | B12: Civil Engineer, Designer (Building Structures / BIM A+) | C12: Ljubljana, SI | F12: Job Board | H12: 46231 | I12: Applied | K12: =IF($H12="","",TODAY()-$H12) | O12: Dejan Batistič | P12: dejan@ikb.si | Q12: slovenia/2026_07_28_ikb_dejan_batistic | R12: High | S12: Near-exact match — posting names 'BIM A+' by name as a qualifying major, which is the candidate's literal degree.
A13: Protim Ržišnik Perc | B13: Mechanical Installation Designer (sprinkler systems) | C13: Šenčur, SI | D13: Hybrid | F13: Job Board | H13: 46232 | I13: Applied | K13: =IF($H13="","",TODAY()-$H13) | O13: Tina Brojan | P13: tina.brojan@rp.si | Q13: slovenia/2026_07_29_protim_rzisnik_perc_tina_brojan | R13: Medium | S13: Strong BIM/MEP overlap but formal degree mismatch (mechanical vs. civil) — addressed honestly.
A14: BOSON d.o.o. | B14: Civil Engineer – Designer for Building Construction | C14: Ljubljana, SI | D14: On-site | F14: Job Board | H14: 46232 | I14: Applied | K14: =IF($H14="","",TODAY()-$H14) | O14: Dr. Aljoša J. Tahir | P14: zaposlitev@boson.si | Q14: slovenia/2026_07_29_boson_aljosa_tahir | R14: Medium | S14: Same role type as Detajl (traffic/municipal infrastructure design).
A15: Standard d.o.o. | B15: Designer – Civil Construction (infrastructure facilities) | C15: Ljubljana, SI | F15: Job Board | H15: 46232 | I15: Applied | K15: =IF($H15="","",TODAY()-$H15) | O15: Peter Berglez | P15: peter.berglez@standard.si | Q15: slovenia/2026_07_29_standard_peter_berglez | R15: Medium | S15: Modest requirements (AutoCAD, MS Office); experience only 'desirable'. Approachable fit.
A16: LynxCraft | B16: Follow-up – student work (no formal posting) | C16: Ljubljana, SI | F16: Networking | H16: 46232 | I16: Applied | J16: Rejected | K16: =IF($H16="","",TODAY()-$H16) | O16: Iztok Šušteršič | P16: iztok@lynx-craft.com | Q16: slovenia/2026_07_29_lynxcraft_iztok_sustersic | R16: High | S16: Warm contact — interviewed March 2026; founder said 'collaborate once funded'. Follow-up re: graduation + ~2mo student availability.
A17: Kolektor Construction | B17: Outreach – student work, intro to other departments (no formal posting) | C17: Logatec, SI | F17: Networking | H17: 46232 | I17: Applied | K17: =IF($H17="","",TODAY()-$H17) | O17: Metod Gaber | P17: Metod.Gaber@kolektor.com | Q17: slovenia/2026_07_29_kolektor_construction_metod_gaber | R17: High | S17: Very warm personal contact; Metod is an active BIM figure at Kolektor (BIMpogovori podcast). Asked for dept. introductions + Slovene commitment (fluent within 2 years).
A18: DCT Group | B18: BIM Coordinator (Porto office) | C18: Porto, PT | D18: Hybrid | F18: Company Site | H18: 46234 | I18: Applied | K18: =IF($H18="","",TODAY()-$H18) | Q18: portugal/2026_07_31_dct | R18: High | S18: Strong match — federated model/clash detection/5D QTO/scan-to-BIM point-cloud all directly relevant. Applied via careers page; open to EU relocation.
A19: Sweco | B19: Junior Systems Engineer (Information Engineering) | C19: Netherlands | D19: Hybrid | F19: Company Site | H19: 46236 | I19: Applied | K19: =IF($H19="","",TODAY()-$H19) | O19: David Peters | P19: david.peters@sweco.nl | Q19: netherlands/2026_08_02_sweco_david_peters | R19: Medium | S19: 0-3 yrs target. Strong conceptual fit (requirements/traceability/verification). Honest that candidate has zero Dutch vs. required 'at least C1'.
A20: Sweco | B20: Junior BIM Modeller – Urban Projects Alkmaar | C20: Alkmaar, NL | D20: Hybrid | F20: Company Site | G20: https://www.sweco.nl/solliciteren/?vacancy=39969 | H20: 46236 | I20: Applied | J20: Rejected | K20: =IF($H20="","",TODAY()-$H20) | O20: Bart Witte | P20: bart.witte@sweco.nl | Q20: netherlands/2026_08_02_sweco_bart_witte | R20: Medium | S20: Best skills-match posting overall (Revit/AutoCAD modelling). Same Dutch C1 gap as the Systems Engineer role.
A21: Sweco | B21: AI and BIM Subject Manager / Head of Department (Rail, Bridge & Tunnel) | C21: Ørestad (Copenhagen), DK | F21: Company Site | H21: 46237 | I21: Applied | K21: =IF($H21="","",TODAY()-$H21) | Q21: denmark/2026_08_03_sweco_head_of_bim_ai | R21: Low | S21: Long-shot per user request — senior Head of Department role requiring solid infrastructure/leadership experience candidate lacks. Leans on BIMGraphExplorer (LLM agent) + Autodesk ACC as genuine overlap. No named contact given.
A22: Sweco | B22: BIM Coordinator – Technical Building Equipment (m/f/x), Job No. S2921 | C22: Munich, DE | F22: Company Site | G22: https://www.sweco-services.de/bms.nsf/Bewerbung?openform&job=S2921 | H22: 46237 | I22: Applied | K22: =IF($H22="","",TODAY()-$H22) | Q22: germany/2026_08_03_sweco_munich_bim_coordinator | R22: Low | S22: Stacked gaps: several years experience required, LINEAR/ALPI software not held, German mandatory (candidate has none). Applied anyway, honest about all three. First German-market CV variant (DOB/nationality added, MM.YYYY dates, no photo — flagged not fabricated).
A23: Bayards Aluminium Solutions | B23: Cost Proposal Engineer – Aluminium Solutions | C23: Nieuw-Lekkerland, NL | F23: Company Site | H23: 46238 | I23: Applied | J23: Rejected | K23: =IF($H23="","",TODAY()-$H23) | P23: work@bayards.com | Q23: netherlands/2026_08_04_bayards | R23: Medium | S23: Strong content match (5D QTO coursework, Contract Management internship pricing/contract review). Honest that candidate has zero Dutch vs. required proficiency in both Dutch and English.
A24: Arup | B24: Junior Bridge Engineer (Bridge & Civil Structures), Job AMS000074 | C24: Amsterdam, NL | D24: Hybrid | F24: Company Site | H24: 46238 | I24: Applied | K24: =IF($H24="","",TODAY()-$H24) | Q24: netherlands/2026_08_04_arup_junior_bridge_engineer | R24: Medium | S24: Junior-friendly seniority fit, but real gaps in FEM/structural calculations (candidate specializes in BIM coordination, not structural analysis) and Dutch B1 (candidate has none). Per user instruction, CV/letter do NOT disclose these gaps — lean only on genuine parametric-design/automation strengths.
A25: Arup | B25: Junior Project Manager – Science, Industry & Technology | C25: Frankfurt, DE | D25: Hybrid | F25: Company Site | H25: 46238 | I25: Applied | K25: =IF($H25="","",TODAY()-$H25) | Q25: germany/2026_08_04_arup_frankfurt_junior_pm | R25: Medium | S25: Junior-friendly (internships/student activities explicitly welcomed). Real gap: "very good German" required, candidate has none. Per updated default, CV/letter do not disclose this gap.
A26: Arup | B26: Assistant Computational Designer – Digital Team | C26: Milan, IT | F26: Company Site | H26: 46238 | I26: Applied | K26: =IF($H26="","",TODAY()-$H26) | Q26: italy/2026_08_04_arup_milan_computational_designer | R26: High | S26: Excellent fit — explicitly welcomes recent graduates, no language gap beyond English, strong overlap on Python/Dynamo/Revit/Git/AI-agent work and GIS (ArcGIS). No major mismatch to flag.
A27: Arup | B27: Open Application – Design Manager, Private & Government Property, Job AMS000091 | C27: Amsterdam, NL | F27: Company Site | G27: https://jobs.arup.com/jobs/33871/other-jobs-matching/location-only | H27: 46238 | I27: Applied | K27: =IF($H27="","",TODAY()-$H27) | Q27: netherlands/2026_08_04_arup_amsterdam_design_manager | R27: Medium | S27: Open solicitation (not a live vacancy), junior-friendly. Real gap: fluent Dutch required, candidate has none. Per updated default, CV/letter do not disclose this gap.
A28: Arup | B28: Open Application – Project Management, Science & Industry, Job AMS000094 | C28: Amsterdam, NL | F28: Company Site | G28: https://jobs.arup.com/jobs/33686/other-jobs-matching/location-only | H28: 46238 | I28: Applied | K28: =IF($H28="","",TODAY()-$H28) | Q28: netherlands/2026_08_04_arup_amsterdam_science_industry_pm | R28: Medium | S28: Open solicitation (not a live vacancy), junior-friendly, same shape as the Design Manager open application. Real gap: fluent Dutch required, candidate has none — not disclosed per updated default.
A29: Arup | B29: Open Application – Project Management, Technology / Data Centers, Job AMS000092 | C29: Amsterdam, NL | F29: Company Site | G29: https://jobs.arup.com/jobs/33870/other-jobs-matching/location-only | H29: 46238 | I29: Applied | K29: =IF($H29="","",TODAY()-$H29) | Q29: netherlands/2026_08_04_arup_amsterdam_tech_datacenters_pm | R29: Medium | S29: Third Arup Amsterdam open application (open solicitation, not a live vacancy), junior-friendly. Real gap: fluent Dutch required, candidate has none — not disclosed per updated default.
A30: Sweco | B30: Junior Building Physics Consultant – Fire, Environment & Building Physics | C30: Netherlands | D30: Hybrid | F30: Company Site | G30: https://www.sweco.nl/solliciteren/?vacancy=66955 | H30: 46238 | I30: Applied | K30: =IF($H30="","",TODAY()-$H30) | O30: Bas Peeters | P30: bas.peeters@sweco.nl | Q30: netherlands/2026_08_04_sweco_bas_peeters | R30: Low | S30: Real domain mismatch — no daylight/energy/acoustics/fire-safety background at all (different specialization than BIM). Fluent Dutch also required. Applied anyway per explicit user instruction; leans on energy-management coursework + adaptability, gaps not disclosed.
A31: Sweco | B31: Junior Fire Safety Advisor – Fire, Environment & Building Physics | C31: Venlo/Eindhoven, NL | D31: Hybrid | E31: EUR 3,442-4,100/month | F31: Company Site | G31: https://www.sweco.nl/solliciteren/?vacancy=66956 | H31: 46238 | I31: Applied | K31: =IF($H31="","",TODAY()-$H31) | O31: Bas Peeters | P31: bas.peeters@sweco.nl | Q31: netherlands/2026_08_04_sweco_fire_safety_peeters | R31: Low | S31: Same team/manager as the Building Physics Consultant posting; real domain gap (no fire-safety background) plus fluent Dutch required. Applied anyway per established preference for this team; gaps not disclosed.
A32: Sweco | B32: Junior Advisor Cultural Engineering – Environmental and Cultural Engineering Research | C32: Eindhoven, NL | D32: Hybrid | E32: EUR 3,442-4,000/month | F32: Company Site | G32: https://www.sweco.nl/solliciteren/?vacancy=66857 | H32: 46238 | I32: Applied | K32: =IF($H32="","",TODAY()-$H32) | O32: Jules Rutten | P32: jules.rutten@sweco.nl | Q32: netherlands/2026_08_04_sweco_jules_rutten | R32: Medium | S32: Genuine domain fit via real hydrology/water-resources coursework (AutoCAD, HEC-HMS, HEC-RAS) — better fit than the Building Physics/Fire Safety Sweco roles. Dutch C1 required, not disclosed per updated default.
A33: Sweco | B33: (Junior) Architectural BIM Engineer – Logistics and Business Accommodation | C33: De Bilt/Eindhoven/The Hague, NL | D33: Hybrid | E33: EUR 3,750-4,250/month | F33: Company Site | G33: https://www.sweco.nl/solliciteren/?vacancy=66747 | H33: 46238 | I33: Applied | K33: =IF($H33="","",TODAY()-$H33) | O33: Eric Thoma | Q33: netherlands/2026_08_04_sweco_eric_thoma | R33: High | S33: Strong direct BIM match — Revit + multidisciplinary coordination maps closely onto the Guimarães project. Real gaps: 2 years experience, fluent Dutch — not disclosed per updated default.
A34: Sweco | B34: (Junior) Urban Planning Advisor – Urban Projects South (Spatial Development) | C34: Kapelle/Middelburg, NL | D34: Hybrid | E34: EUR 3,600-4,300/month | F34: Company Site | G34: https://www.sweco.nl/solliciteren/?vacancy=66743 | H34: 46238 | I34: Applied | K34: =IF($H34="","",TODAY()-$H34) | O34: Marik Waterman | P34: marik.waterman@sweco.nl | Q34: netherlands/2026_08_04_sweco_marik_waterman | R34: Medium | S34: Surfaced real urban planning coursework (previously untracked). Explicit ask for digitalization/AI experience is a genuine strength. No Dutch requirement listed. 2 years experience gap not disclosed per updated default.
A35: Sweco | B35: (Junior) Transport Pipeline Engineer – Water | C35: De Bilt, NL | D35: Hybrid | E35: EUR 3,600-4,300/month | F35: Company Site | G35: https://www.sweco.nl/solliciteren/?vacancy=66744 | H35: 46238 | I35: Applied | K35: =IF($H35="","",TODAY()-$H35) | O35: John Driessen | P35: john.driessen@sweco.nl | Q35: netherlands/2026_08_04_sweco_john_driessen | R35: Medium | S35: Genuine domain fit via real AutoCAD/ArcGIS/hydrology coursework, matching the posting’s explicit software asks. 1-3 years experience and Dutch C1 gaps not disclosed per updated default.
A36: Sweco | B36: Junior Construction Project Manager – Logistics and Business Accommodation | C36: De Bilt/Amsterdam, NL | D36: Hybrid | E36: EUR 3,500-4,500/month | F36: Company Site | G36: https://www.sweco.nl/solliciteren/?vacancy=66706 | H36: 46238 | I36: Applied | K36: =IF($H36="","",TODAY()-$H36) | P36: lindsay.vanheugten@sweco.nl | Q36: netherlands/2026_08_04_sweco_pm_logistics_thoma | R36: Medium | S36: Same team as the Architectural BIM Engineer application (Eric Thoma). 1-3 years experience and Dutch fluency gaps not disclosed per updated default.
A37: Sweco | B37: Junior Contract Management Advisor – Urban Projects | C37: Rotterdam, NL | D37: Hybrid | E37: EUR 3,442-4,100/month | F37: Company Site | G37: https://www.sweco.nl/solliciteren/?vacancy=66683 | H37: 46238 | I37: Applied | K37: =IF($H37="","",TODAY()-$H37) | O37: Edyta Wisniewska | P37: edyta.wisniewska@sweco.nl | Q37: netherlands/2026_08_04_sweco_edyta_wisniewska | R37: High | S37: Strong match — graduate-entry framing, no Dutch requirement listed, and the FIDIC contract-review internship maps directly onto the role.
A38: Sweco | B38: (Junior) Project Manager – Volantis | C38: Venlo/Eindhoven, NL | D38: Hybrid | F38: Company Site | G38: https://www.sweco.nl/solliciteren/?vacancy=66682 | H38: 46238 | I38: Applied | K38: =IF($H38="","",TODAY()-$H38) | O38: Pim Uiting | P38: pim.uiting@sweco.nl | Q38: netherlands/2026_08_04_sweco_volantis_pim_uiting | R38: Medium | S38: Graduate-friendly ("starters also welcome"). Fluent Dutch and English required, not disclosed per updated default.
A39: Sweco | B39: Junior Soil Consultant – Environmental Consultancy | C39: Groningen, NL | D39: Hybrid | E39: EUR 3,442-4,100/month | F39: Company Site | G39: https://www.sweco.nl/solliciteren/?vacancy=66601 | H39: 46238 | I39: Applied | K39: =IF($H39="","",TODAY()-$H39) | O39: Mariska Moyaert | P39: mariska.moyaert@sweco.nl | Q39: netherlands/2026_08_04_sweco_mariska_moyaert | R39: Medium | S39: Domain-adjacent fit via real hydrology/water-resources/GIS coursework. Recent graduates explicitly welcomed. Dutch gap not disclosed per updated default.
A40: Sweco | B40: Junior Fire Safety Advisor – Fire Safety & Simulations | C40: Amsterdam/Venlo/De Bilt/Rotterdam/Eindhoven, NL | D40: Hybrid | E40: EUR 3,442-4,000/month | F40: Company Site | G40: https://www.sweco.nl/solliciteren/?vacancy=66548 | H40: 46238 | I40: Applied | K40: =IF($H40="","",TODAY()-$H40) | O40: Bart de Vries | P40: bart.devries@sweco.nl | Q40: netherlands/2026_08_04_sweco_bart_de_vries | R40: Low | S40: Same domain gap as the earlier Peeters Fire Safety application (different team: Fire Safety & Simulations). No fire-safety/CFD background. Dutch B2 minimum not disclosed per updated default.
...

Sheet Lists
A1: Stage | B1: Outcome | C1: Work Setup | D1: Source | E1: Priority | G1: Edit these lists to change the dropdown options on the Applications tab.
A2: To Apply | B2: Rejected | C2: Remote | D2: LinkedIn | E2: High
A3: Applied | B3: Ghosted | C3: Hybrid | D3: Company Site | E3: Medium
A4: Phone Screen | B4: Withdrawn | C4: On-site | D4: Referral | E4: Low
A5: Interview | B5: Offer Accepted | D5: Recruiter
A6: Final Round | B6: Offer Declined | D6: Indeed
A7: Offer | D7: Glassdoor
D8: Job Board
D9: Networking
D10: Other
